<?xml version="1.0"?>
<robot name="myRobot">

  <material name="orange">
    <color rgba="1 0.65 0 1"/>
  </material>
  <material name="black">
    <color rgba="0 0 0 1"/>
  </material>
  <material name="white">
    <color rgba="1 1 1 1"/>
  </material>

  <link name="base_link">
    <visual>
      <origin xyz="0 0 0.3" rpy="1.5708 0 0"/>
      <geometry>
        <cylinder length="0.1" radius="0.3"/>
      </geometry>
      <material name="white"/>
    </visual>
  </link>
  
  <joint name="right_to_base" type="continuous">
    <parent link="base_link"/>
    <child link="right_wheel"/>
    <axis xyz="0 1 0"/>
    <origin xyz="0 0 0.3"/>
  </joint>
  
  <link name="right_wheel">
    <visual>
      <origin xyz="0 -0.05 0"/>
      <geometry>
        <sphere radius="0.3"/>
      </geometry>
      <material name="orange"/>
    </visual>
  </link>

  <joint name="left_to_base" type="continuous">
    <parent link="base_link"/>
    <child link="left_wheel"/>
    <axis xyz="0 1 0"/>
    <origin xyz="0 0 0.3"/>
  </joint>

  <link name="left_wheel">
    <visual>
      <origin xyz="0 0.05 0"/>
      <geometry>
        <sphere radius="0.3"/>
      </geometry>
      <material name="orange"/>
    </visual>
  </link>

  <link name="head">
    <visual>
      <origin xyz="0 0 0"/>
      <geometry>
        <cylinder length="0.1" radius="0.2"/>
      </geometry>
      <material name="black"/>
    </visual>
  </link>

  <joint name="body_to_rotator" type="fixed">
    <parent link="base_link"/>
    <child link="head_rotator"/>
    <origin xyz="0 0 0.6"/>
  </joint>

  <link name="head_rotator">
    <visual>
      <origin xyz="0 0 0"/>
      <geometry>
        <cylinder length="0.05" radius="0.05"/>
      </geometry>
      <material name="black"/>
    </visual>
  </link>

  <joint name="rotator_to_head" type="revolute">
    <limit effort="1000" lower="-1.5708" upper="1.5708" velocity="0.5"/>
    <parent link="head_rotator"/>
    <child link="head"/>
    <axis xyz="0 0 1"/>
    <origin xyz="0 0 0.05"/>
  </joint>

</robot>
